Workbook
Name Base_Cost_180deg_Belt_Curve: #REF!
Name Base_Cost_180deg_Belt_Curve: #REF!
Name Base_Cost_180deg_Roller_Curve: #REF!
Name Base_Cost_180deg_Roller_Curve: #REF!
Name Base_Cost_30deg_Belt_Curve: #REF!
Name Base_Cost_30deg_Belt_Curve: #REF!
Name Base_Cost_30deg_Roller_Curve: #REF!
Name Base_Cost_30deg_Roller_Curve: #REF!
Name Base_Cost_45deg_Belt_Curve: #REF!
Name Base_Cost_45deg_Belt_Curve: #REF!
Name Base_Cost_45deg_Roller_Curve: #REF!
Name Base_Cost_45deg_Roller_Curve: #REF!
Name Base_Cost_60deg_Belt_Merge: #REF!
Name Base_Cost_60deg_Belt_Merge: #REF!
Name Base_Cost_60deg_Roller_Curve: #REF!
Name Base_Cost_60deg_Roller_Curve: #REF!
Name Base_Cost_90deg_Belt_Merge: #REF!
Name Base_Cost_90deg_Belt_Merge: #REF!
Name Base_Cost_90deg_Roller_Curve: #REF!
Name Base_Cost_90deg_Roller_Curve: #REF!
Name Base_Cost_Accumulation_Roller: #REF!
Name Base_Cost_Accumulation_Roller: #REF!
Name Base_Cost_Belt_Decline: #REF!
Name Base_Cost_Belt_Decline: #REF!
Name Base_Cost_Belt_Incline: #REF!
Name Base_Cost_Belt_Incline: #REF!
Name Base_Cost_Belt_Merge: #REF!
Name Base_Cost_Belt_Merge: #REF!
Name Base_Cost_Belt_Transport: #REF!
Name Base_Cost_Belt_Transport: #REF!
Name Base_Cost_Belt_Under_Roller: #REF!
Name Base_Cost_Belt_Under_Roller: #REF!
Name Base_Cost_Gravity_Roller: #REF!
Name Base_Cost_Gravity_Roller: #REF!
Name Base_Cost_Gravity_Spur: #REF!
Name Base_Cost_Gravity_Spur: #REF!
Name Base_Cost_Lineshaft_Roller: #REF!
Name Base_Cost_Lineshaft_Roller: #REF!
Name Base_Cost_Metering_Belt: #REF!
Name Base_Cost_Metering_Belt: #REF!
Name Base_Cost_Photo_Eyes: #REF!
Name Base_Cost_Photo_Eyes: #REF!
Name Base_Cost_Power_Feeder: #REF!
Name Base_Cost_Power_Feeder: #REF!
Name Base_Cost_Powered_Roller_Spur: #REF!
Name Base_Cost_Powered_Roller_Spur: #REF!
Name Belt_Width: #REF!
Name Belt_Width: #REF!
Name BeltCost: #REF!
Name BeltCost: #REF!
Name BeltType: '[1]Main Page'!$J$3
Name BodyHeight: #REF!
Name BodyHeight: #REF!
Name BodySection: '[1]Main Page'!$D$3
Name BTP10Price: [2]Sheet4!$G$115
Name BTP11Price: [2]Sheet4!$G$125
Name BTP1Price: [2]Sheet4!$G$21
Name BTP2Price: [2]Sheet4!$G$33
Name BTP3Price: [2]Sheet4!$G$43
Name BTP4Price: [2]Sheet4!$G$53

Sheet Final 
A1: S. No | B1: Component | C1: Qty per set | D1: Set | E1: UOM | G1: Price
A2: 1 | B2: CBS, Induct & Scanning Package | C2: 1 | D2: 1 | E2: Set | F2: € | G2: ='Overall Costing'!J2 -> 1311723.2 | L2: Preventive Maintenance for 2 days | M2: =4*500 -> 2000
A3: 2 | B3: Infeed Conveyors & VDS Package | C3: 1 | D3: 1 | E3: Set | F3: € | G3: ='Overall Costing'!J3+'Overall Costing'!J4 -> 842200.81 | L3: PM for 1 Year (1 in each month) | M3: =M2*12 -> 24000
A4: 3 | B4: Chute Package | C4: 1 | D4: 1 | E4: Set | F4: € | G4: ='Overall Costing'!J5 -> 400836.41 | L4: Breakdown Visit 12 Nos | M4: =12*1000 -> 12000
A5: 4 | B5: Mezannine Package | C5: 1 | D5: 1 | E5: Set | F5: € | G5: ='Overall Costing'!J6 -> 629102.13 | M5: =SUM(M3:M4) -> 36000
A6: 4 | B6: Software Packages | C6: 1 | D6: 1 | E6: Set | F6: € | G6: ='Overall Costing'!J8 -> 15957.447
A7: 5 | B7: Installation & Commissioning | C7: 1 | D7: 1 | E7: Set | F7: € | G7: ='Overall Costing'!J9+'Overall Costing'!J12+'Overall Costing'!J14 -> 604556.17
A8: 6 | B8: Packaging & Documentation | C8: 1 | D8: 1 | E8: Set | F8: € | G8: ='Overall Costing'!J10 -> 159193.13
A9: 7 | B9: Project Management and Engineering Charges | C9: 1 | D9: 1 | E9: Set | F9: € | G9: ='Overall Costing'!J11 -> 98078.468
A10: 8 | B10: Freight | C10: 1 | D10: 1 | E10: Set | F10: € | G10: ='Overall Costing'!J13 -> 204545.45
A11: 9 | B11: Spare Kit as per Inpost List | C11: 1 | D11: 1 | E11: Set | F11: € | G11: ='Overall Costing'!J15 -> 63869.011
A12: 10 | B12: Protection on Ground | C12: 1 | D12: 1 | E12: Set | F12: € | G12: ='Overall Costing'!J16 -> 15957.447 | H12: =SUM(G2:G12) -> 4346019.7
A13: Total Package for 1 Sorter per Piece | F13: € | G13: =SUM(G2:G12) -> 4346019.7
A14: Total Package for 2 Sorters per piece | F14: € | G14: ='[5]Final '!$G$13 -> 3548906.5
A15: Total Package for 3 Sorters per piece | F15: € | G15: ='[6]Final '!$G$13 -> 3507251.9
A16: 11 | B16: Recommended Spare Package by Falcon | C16: 1 | D16: 1 | E16: Set | F16: € | G16: ='Overall Costing'!J19 -> 204380.84
A17: 12 | B17: Hotline Support | C17: 1 | D17: 1 | E17: Set | F17: € | G17: 45000
A18: 13 | B18: Warranty Inspection | C18: 1 | D18: 1 | E18: Set | F18: € | G18: 36000

Sheet Inpost Sheet
A1: S. No | B1: Component | C1: Qty per set | D1: Set | E1: UOM | F1: Price
A2: 1 | B2: CBS & Scanning | C2: 1 | D2: 1 | E2: Set | F2: ='Loop CBS'!D70+'Loop CBS'!D132-F7-F8 -> 855583.84
A3: =A2+1 -> 2 | B3: Outbound Manual Chutes | C3: 1 | D3: 1 | E3: Set | F3: =Destinations!F26 -> 320051.31
A4: =A3+1 -> 3 | B4: Inbound Manual Lines | C4: 1 | D4: 1 | E4: Set | F4: =Conveyors!N75+'Overall Costing'!J3 -> 283929.23
A5: =A4+1 -> 4 | B5: Inbound Reject Lines | C5: 1 | D5: 1 | E5: Set | F5: =Conveyors!N76 -> 113652.84
A6: =A5+1 -> 5 | B6: Sorter Induct Line | C6: 1 | D6: 1 | E6: Set | F6: ='Loop CBS'!D130 -> 240378.93
A7: =A6+1 -> 6 | B7: Dimesnion Checking System | F7: ='Loop CBS'!D56 -> 32939.322
A8: =A7+1 -> 7 | B8: Scanning Gate | F8: ='Loop CBS'!D51 -> 182821.12
A9: =A8+1 -> 8 | B9: Maintenance Platform | C9: 1 | D9: 1 | E9: Set | F9: =Steelworks!H10 -> 629102.13
A10: =A9+1 -> 9 | B10: Protection on the ground of sorter | C10: 1 | D10: 1 | E10: Set | F10: ='Overall Costing'!J16 -> 15957.447 | J10: 45855
A11: =A10+1 -> 10 | B11: Project management | C11: 1 | D11: 1 | E11: Set | F11: ='Overall Costing'!J11 -> 98078.468 | J11: 46120
A12: =A11+1 -> 11 | B12: mechanical installation | C12: 1 | D12: 1 | E12: Set | F12: ='I&C Cost'!D2 -> 343752.13
A13: =A12+1 -> 12 | B13: electrical installation | C13: 1 | D13: 1 | E13: Set | F13: ='I&C Cost'!D3 -> 113026.91 | J13: =J11-J10 -> 265
A14: =A13+1 -> 13 | B14: commisioning | C14: 1 | D14: 1 | E14: Set | F14: ='I&C Cost'!D4 -> 30919.149 | J14: =J13/30 -> 8.8333333
A15: =A14+1 -> 14 | B15: I.T. software implementation | C15: 1 | D15: 1 | E15: Set | F15: ='I&C Cost'!D5+'Overall Costing'!J8 -> 30981.383
A16: =A15+1 -> 15 | B16: Acceptance Test | C16: 1 | D16: 1 | E16: Set | F16: ='Overall Costing'!J12 -> 44636.17
A17: =A16+1 -> 16 | B17: Support Ramp Up | C17: 1 | D17: 1 | E17: Set | F17: ='Overall Costing'!J14 -> 12197.872
A18: =A17+1 -> 17 | B18: Transport & Packaging | C18: 1 | D18: 1 | E18: Set | F18: ='Overall Costing'!J10+'Overall Costing'!J13 -> 363738.58
A19: =A18+1 -> 18 | B19: Field Wiring | C19: 1 | D19: 1 | E19: Set | F19: =Conveyors!N77 -> 97325.737
A20: =A19+1 -> 19 | B20: Chute Accessories | C20: 1 | D20: 1 | E20: Set | F20: =Destinations!F27 -> 80785.106
A21: =A20+1 -> 20 | B21: Spare Kit | C21: 1 | D21: 1 | E21: Set | F21: ='Overall Costing'!J15 -> 63869.011 | G21: =F21*92 -> 5875949
A22: =A21+1 -> 21 | B22: Others (MHE,Waste Management,) | C22: 1 | D22: 1 | E22: Set | F22: ='I&C Cost'!D6+'I&C Cost'!D7+'I&C Cost'!D8 -> 45000
A23: Total System Package | F23: =SUM(F2:F22) -> 3998726.7 | G23: =F23-'Overall Costing'!J17 -> -363696.48
A24: Warranty Inspection | F24: ='Final '!G18 -> 36000
A25: Hotline Support | F25: 45000
A26: Recommended Spare Package | F26: ='Overall Costing'!J19 -> 204380.84

Sheet Support Rampup
A1: B. FALCON HO TEAM
A2: Charges
A3: Person | B3: NO. OF MANPOWER REQUIRED | C3: No. of working days required | D3: AIR FARE | E3: VISA | F3: HOTEL | G3: MAN DAY COST | H3: DAILY ALLOWANCE
A4: Site Manager | B4: 1 | C4: 12 | D4: 90000 | E4: 25000 | F4: 9000 | G4: 9000 | H4: 9000
A5: Mechanical Engineer | B5: 0 | C5: 0 | D5: =D4 -> 90000 | E5: =E4 -> 25000 | F5: =F4 -> 9000 | G5: 6000 | H5: =H4 -> 9000
A6: Electrical Engineer | B6: 1 | C6: 12 | D6: =D5 -> 90000 | E6: =E5 -> 25000 | F6: =F5 -> 9000 | G6: 6000 | H6: =H5 -> 9000
A7: PLC | B7: 1 | C7: 12 | D7: =D6 -> 90000 | E7: =E6 -> 25000 | F7: =F6 -> 9000 | G7: 9000 | H7: =H6 -> 9000
A8: PLC Engineer | B8: 1 | C8: 0 | D8: =D7 -> 90000 | E8: =E7 -> 25000 | F8: =F7 -> 9000 | G8: 9000 | H8: =H7 -> 9000
A9: IT Engineer | B9: 1 | C9: 0 | D9: =D7 -> 90000 | E9: =E7 -> 25000 | F9: =F7 -> 9000 | G9: 12000 | H9: =H7 -> 9000
A11: Cost Calculation
A13: FALCON SUPERVISORS REQUIRED | B13: Total NO. OF DAYS REQUIRED | C13: AIR FARE | D13: VISA | E13: HOTEL | F13: MAN DAY COST | G13: DAILY ALLOWANCE
A14: Project Supervisor | B14: =ROUNDUP(C4*7/6,0) -> 14 | C14: =B4*D4 -> 90000 | D14: =B4*E4 -> 25000 | E14: =B4*(B14)*F4 -> 126000 | F14: =B4*B14*G4 -> 126000 | G14: =B4*(B14)*H4 -> 126000
A15: Mechanical Supervisor | B15: =ROUNDUP(C5*7/6,0) -> 0 | C15: =B5*D5 -> 0 | D15: =B5*E5 -> 0 | E15: =B5*(B15)*F5 -> 0 | F15: =B5*B15*G5 -> 0 | G15: =B5*(B15)*H5 -> 0 | H15: =ROUNDUP(#REF!/(8*6),0) -> #REF!
A16: Electrical Supervisor | B16: =ROUNDUP(C6*7/6,0) -> 14 | C16: =B6*D6 -> 90000 | D16: =B6*E6 -> 25000 | E16: =B6*(B16)*F6 -> 126000 | F16: =B6*B16*G6 -> 84000 | G16: =B6*(B16)*H6 -> 126000
A17: PLC Programmer | B17: =ROUNDUP(C7*7/6,0) -> 14 | C17: =B7*D7 -> 90000 | D17: =B7*E7 -> 25000 | E17: =B7*((B17))*F7 -> 126000 | F17: =B7*B17*G7 -> 126000 | G17: =B7*(B17)*H7 -> 126000
A18: IT Engineer | B18: =ROUNDUP(C8*7/6,0) -> 0 | C18: =B8*D8 -> 90000 | D18: =B8*E8 -> 25000 | E18: =B8*((B18))*F8 -> 0 | F18: =B8*B18*G8 -> 0 | G18: =B8*(B18)*H8 -> 0
A19: IT Engineer | B19: =ROUNDUP(C9*7/6,0) -> 0 | C19: =B9*D9 -> 90000 | D19: =B9*E9 -> 25000 | E19: =B9*(B19)*F9 -> 0 | F19: =B9*B19*G9 -> 0 | G19: =B9*(B19)*H9 -> 0
B20: Total Cost (INR) | C20: 0 | D20: 0 | E20: =SUM(E14:E19) -> 378000 | F20: =SUM(F14:F19) -> 336000 | G20: =SUM(G14:G19) -> 378000
B21: Total Cost (EUR) | C21: =C20/'[7]Overall Costing'!N2 -> 0 | D21: =D20/'[7]Overall Costing'!N2 -> 0 | E21: =E20/'[7]Overall Costing'!N2 -> 4344.8276 | F21: =F20/'[7]Overall Costing'!N2 -> 3862.069 | G21: =G20/'[7]Overall Costing'!N2 -> 4344.8276
B24: Total Falcon Team Cost (B) | C24: =SUM(C21:G21) -> 12551.724 | D24: =SUM(C20:G20) -> 1092000
B25: FOS | C25: 0.05
B26: Final Quote | C26: =C24*(1+C25) -> 13179.31 | D26: =D24*(1+C25) -> 1146600
B27: Insurance | D27: =C27*'[8]Overall Costing'!M5 -> 0
D28: =SUM(D26:D27) -> 1146600 | E28: =D28/'Overall Costing'!M5 -> 12197.872

Sheet I&C Cost
B2: Mechanical Installation Cost | C2: ='Local I&C'!E2+'FAPL I&C'!J14 -> 327382.98 | D2: =C2*(1+5%) -> 343752.13 | I2: Container Cost | J2: =400000*1.25 -> 500000
B3: Electrical Installation Cost | C3: ='Local I&C'!E3+'FAPL I&C'!J16 -> 107644.68 | D3: =C3*(1+5%) -> 113026.91 | I3: Container Cost | J3: =J2/88 -> 5681.8182
B4: PLC Comissioning Cost | C4: ='FAPL I&C'!J17+'FAPL I&C'!J18 -> 29446.809 | D4: =C4*(1+5%) -> 30919.149 | I4: For 36 Nos Containers from India | J4: =J3*36 -> 204545.45
B5: IT Comissioning Cost | C5: ='FAPL I&C'!J19 -> 14308.511 | D5: =C5*(1+5%) -> 15023.936 | I5: For Chute from Poland | J5: 0
B6: MHEs | D6: ='Local I&C'!E8 -> 20000 | I6: Total | J6: =J4+J5 -> 204545.45
B7: Waste Management | D7: ='Local I&C'!E9 -> 15000 | I7: Total | J7: =J6*'Overall Costing'!M5 -> 19227273
B8: Insurance Cost | D8: ='FAPL I&C'!C27 -> 10000

Sheet Local I&C
A1: Team | B1: Mandays | C1: Manhours | D1: Manhour Rate | E1: Price
A2: Technician | B2: 800 | C2: =B2*10 -> 8000 | D2: 37 | E2: =D2*C2 -> 296000
A3: Electrician | B3: 220 | C3: =B3*10 -> 2200 | D3: 37 | E3: =D3*C3 -> 81400
D4: Total Manpower Cost | E4: =SUM(E2:E3) -> 377400
D5: Factor of Saftey | E5: 0.05
D6: Final Manpower Cost | E6: =(E4*E5)+E4 -> 396270
D7: VAT | E7: =E6*0% -> 0
D8: Material Handling Equipment | E8: 20000
D9: Waste Management | E9: 15000
D10: Over all Cost | E10: =E6+E7+E9+E8 -> 431270 | F10: =E10*'Overall Costing'!M5 -> 40539380
F13: =E10+'[8]FAPl I&C'!C26 -> 489654.48

Sheet FAPL SAT
A1: B. FALCON HO TEAM
A2: Charges
A3: Person | B3: NO. OF MANPOWER REQUIRED | C3: No. of working days required | D3: AIR FARE | E3: VISA | F3: HOTEL | G3: MAN DAY COST | H3: DAILY ALLOWANCE
A4: Site Manager | B4: 1 | C4: =24+7 -> 31 | D4: 90000 | E4: 25000 | F4: 9000 | G4: 9000 | H4: 9000
A5: Mechanical Engineer | B5: 0 | C5: 0 | D5: =D4 -> 90000 | E5: =E4 -> 25000 | F5: =F4 -> 9000 | G5: 6000 | H5: =H4 -> 9000
A6: Electrical Engineer | B6: 1 | C6: =24+7 -> 31 | D6: =D5 -> 90000 | E6: =E5 -> 25000 | F6: =F5 -> 9000 | G6: 6000 | H6: =H5 -> 9000
A7: PLC | B7: 1 | C7: =24+7 -> 31 | D7: =D6 -> 90000 | E7: =E6 -> 25000 | F7: =F6 -> 9000 | G7: 9000 | H7: =H6 -> 9000
A8: PLC Engineer | B8: 1 | C8: 0 | D8: =D7 -> 90000 | E8: =E7 -> 25000 | F8: =F7 -> 9000 | G8: 9000 | H8: =H7 -> 9000
A9: IT Engineer | B9: 1 | C9: =24+7 -> 31 | D9: =D7 -> 90000 | E9: =E7 -> 25000 | F9: =F7 -> 9000 | G9: 12000 | H9: =H7 -> 9000
A11: Cost Calculation
A13: FALCON SUPERVISORS REQUIRED | B13: Total NO. OF DAYS REQUIRED | C13: AIR FARE | D13: VISA | E13: HOTEL | F13: MAN DAY COST | G13: DAILY ALLOWANCE
A14: Project Supervisor | B14: =ROUNDUP(C4*7/6,0) -> 37 | C14: =B4*D4 -> 90000 | D14: =B4*E4 -> 25000 | E14: =B4*(B14)*F4 -> 333000 | F14: =B4*B14*G4 -> 333000 | G14: =B4*(B14)*H4 -> 333000
A15: Mechanical Supervisor | B15: =ROUNDUP(C5*7/6,0) -> 0 | C15: =B5*D5 -> 0 | D15: =B5*E5 -> 0 | E15: =B5*(B15)*F5 -> 0 | F15: =B5*B15*G5 -> 0 | G15: =B5*(B15)*H5 -> 0 | H15: =ROUNDUP(#REF!/(8*6),0) -> #REF!
A16: Electrical Supervisor | B16: =ROUNDUP(C6*7/6,0) -> 37 | C16: =B6*D6 -> 90000 | D16: =B6*E6 -> 25000 | E16: =B6*(B16)*F6 -> 333000 | F16: =B6*B16*G6 -> 222000 | G16: =B6*(B16)*H6 -> 333000
A17: PLC Programmer | B17: =ROUNDUP(C7*7/6,0) -> 37 | C17: =B7*D7 -> 90000 | D17: =B7*E7 -> 25000 | E17: =B7*((B17))*F7 -> 333000 | F17: =B7*B17*G7 -> 333000 | G17: =B7*(B17)*H7 -> 333000
A18: IT Engineer | B18: =ROUNDUP(C8*7/6,0) -> 0 | C18: =B8*D8 -> 90000 | D18: =B8*E8 -> 25000 | E18: =B8*((B18))*F8 -> 0 | F18: =B8*B18*G8 -> 0 | G18: =B8*(B18)*H8 -> 0
A19: IT Engineer | B19: =ROUNDUP(C9*7/6,0) -> 37 | C19: =B9*D9 -> 90000 | D19: =B9*E9 -> 25000 | E19: =B9*(B19)*F9 -> 333000 | F19: =B9*B19*G9 -> 444000 | G19: =B9*(B19)*H9 -> 333000
B20: Total Cost (INR) | C20: 0 | D20: 0 | E20: =SUM(E14:E19) -> 1332000 | F20: =SUM(F14:F19) -> 1332000 | G20: =SUM(G14:G19) -> 1332000
B21: Total Cost (EUR) | C21: =C20/'[7]Overall Costing'!N2 -> 0 | D21: =D20/'[7]Overall Costing'!N2 -> 0 | E21: =E20/'[7]Overall Costing'!N2 -> 15310.345 | F21: =F20/'[7]Overall Costing'!N2 -> 15310.345 | G21: =G20/'[7]Overall Costing'!N2 -> 15310.345
B24: Total Falcon Team Cost (B) | C24: =SUM(C21:G21) -> 45931.034 | D24: =SUM(C20:G20) -> 3996000
B25: FOS | C25: 0.05
B26: Final Quote | C26: =C24*(1+C25) -> 48227.586 | D26: =D24*(1+C25) -> 4195800
B27: Insurance | D27: =C27*'[8]Overall Costing'!M5 -> 0
D28: =SUM(D26:D27) -> 4195800 | E28: =D28/'Overall Costing'!M5 -> 44636.17

Sheet FAPL I&C
A1: B. FALCON HO TEAM
A2: Charges
A3: Person | B3: NO. OF MANPOWER REQUIRED | C3: No. of working days required | D3: AIR FARE | E3: VISA | F3: HOTEL | G3: MAN DAY COST | H3: DAILY ALLOWANCE
A4: Site Manager | B4: 1 | C4: 90 | D4: 90000 | E4: 25000 | F4: 9000 | G4: 9000 | H4: 9000
A5: Mechanical Engineer | B5: 0 | C5: 0 | D5: =D4 -> 90000 | E5: =E4 -> 25000 | F5: =F4 -> 9000 | G5: 6000 | H5: =H4 -> 9000
A6: Electrical Engineer | B6: 1 | C6: 84 | D6: =D5 -> 90000 | E6: =E5 -> 25000 | F6: =F5 -> 9000 | G6: 6000 | H6: =H5 -> 9000
A7: PLC | B7: 1 | C7: 40 | D7: =D6 -> 90000 | E7: =E6 -> 25000 | F7: =F6 -> 9000 | G7: 9000 | H7: =H6 -> 9000
A8: PLC | B8: 1 | C8: 40 | D8: =D7 -> 90000 | E8: =E7 -> 25000 | F8: =F7 -> 9000 | G8: 9000 | H8: =H7 -> 9000
A9: IT Engineer | B9: 1 | C9: 35 | D9: =D7 -> 90000 | E9: =E7 -> 25000 | F9: =F7 -> 9000 | G9: 12000 | H9: =H7 -> 9000
A11: Cost Calculation
A13: FALCON SUPERVISORS REQUIRED | B13: Total NO. OF DAYS REQUIRED | C13: AIR FARE | D13: VISA | E13: HOTEL | F13: MAN DAY COST | G13: DAILY ALLOWANCE | I13: Total | J13: Total
A14: Project Supervisor | B14: =ROUNDUP(C4*7/6,0) -> 105 | C14: =B4*D4 -> 90000 | D14: =B4*E4 -> 25000 | E14: =B4*(B14)*F4 -> 945000 | F14: =B4*B14*G4 -> 945000 | G14: =B4*(B14)*H4 -> 945000 | I14: =SUM(C14:G14) -> 2950000 | J14: =I14/'Overall Costing'!$M$5 -> 31382.979
A15: Mechanical Supervisor | B15: =ROUNDUP(C5*7/6,0) -> 0 | C15: =B5*D5 -> 0 | D15: =B5*E5 -> 0 | E15: =B5*(B15)*F5 -> 0 | F15: =B5*B15*G5 -> 0 | G15: =B5*(B15)*H5 -> 0 | I15: =SUM(C15:G15) -> 0 | J15: =I15/'Overall Costing'!$M$5 -> 0
A16: Electrical Supervisor | B16: =ROUNDUP(C6*7/6,0) -> 98 | C16: =B6*D6 -> 90000 | D16: =B6*E6 -> 25000 | E16: =B6*(B16)*F6 -> 882000 | F16: =B6*B16*G6 -> 588000 | G16: =B6*(B16)*H6 -> 882000 | I16: =SUM(C16:G16) -> 2467000 | J16: =I16/'Overall Costing'!$M$5 -> 26244.681
A17: PLC Programmer | B17: =ROUNDUP(C7*7/6,0) -> 47 | C17: =B7*D7 -> 90000 | D17: =B7*E7 -> 25000 | E17: =B7*((B17))*F7 -> 423000 | F17: =B7*B17*G7 -> 423000 | G17: =B7*(B17)*H7 -> 423000 | I17: =SUM(C17:G17) -> 1384000 | J17: =I17/'Overall Costing'!$M$5 -> 14723.404
A18: PLC Programmer | B18: =ROUNDUP(C8*7/6,0) -> 47 | C18: =B8*D8 -> 90000 | D18: =B8*E8 -> 25000 | E18: =B8*((B18))*F8 -> 423000 | F18: =B8*B18*G8 -> 423000 | G18: =B8*(B18)*H8 -> 423000 | I18: =SUM(C18:G18) -> 1384000 | J18: =I18/'Overall Costing'!$M$5 -> 14723.404
A19: IT Engineer | B19: =ROUNDUP(C9*7/6,0) -> 41 | C19: =B9*D9 -> 90000 | D19: =B9*E9 -> 25000 | E19: =B9*(B19)*F9 -> 369000 | F19: =B9*B19*G9 -> 492000 | G19: =B9*(B19)*H9 -> 369000 | I19: =SUM(C19:G19) -> 1345000 | J19: =I19/'Overall Costing'!$M$5 -> 14308.511
B20: Total Cost (INR) | C20: =SUM(C14:C19) -> 450000 | D20: =SUM(D14:D19) -> 125000 | E20: =SUM(E14:E19) -> 3042000 | F20: =SUM(F14:F19) -> 2871000 | G20: =SUM(G14:G19) -> 3042000
B21: Total Cost (EUR) | C21: =C20/'Overall Costing'!$M$5 -> 4787.234 | D21: =D20/'Overall Costing'!$M$5 -> 1329.7872 | E21: =E20/'Overall Costing'!$M$5 -> 32361.702 | F21: =F20/'Overall Costing'!$M$5 -> 30542.553 | G21: =G20/'Overall Costing'!$M$5 -> 32361.702
B24: Total Falcon Team Cost (B) | C24: =SUM(C21:G21) -> 101382.98 | D24: =SUM(C20:G20) -> 9530000
B25: FOS | C25: 0.05
B26: Final Quote | C26: =C24*(1+C25) -> 106452.13 | D26: =D24*(1+C25) -> 10006500
B27: Insurance | C27: 10000 | D27: =C27*'Overall Costing'!M5 -> 940000
C28: =SUM(C26:C27) -> 116452.13 | D28: =SUM(D26:D27) -> 10946500

Sheet Overall Costing
A1: Sr. No | B1: Component | D1: Qty per set | E1: Set | F1: UOM | G1: Unit Rate | H1: Total(INR) | I1: Hiked INR | J1: =L5 -> EURO | K1: Family | L1: Sales Factor | M1: 0.675
A2: 1 | B2: Loop Cross Belt Sorter with VMS, ICR | D2: 1 | E2: 1 | F2: Set | G2: =+'Loop CBS'!C133 -> 1.2330198e+08 | H2: =G2*E2*D2 -> 1.2330198e+08 | I2: =H2*$M$2 -> 1.2330198e+08 | J2: =I2/$M$5 -> 1311723.2 | K2: Sorter + Scanning + Server + Induct Lines | L2: Hiked INR Factor | M2: 1
A3: 2 | B3: Arm Sorter | D3: 1 | E3: 1 | F3: Set | G3: =+'Arm Sorter'!C42 -> 16890000 | H3: =G3*E3*D3 -> 16890000 | I3: =H3*$M$2 -> 16890000 | J3: =I3/$M$5 -> 179680.85 | K3: Sorter+ Induct Lines | L3: Field wiring and controls | M3: 0.15
A4: 3 | B4: Conveyors | D4: 1 | E4: 1 | F4: Set | G4: =Conveyors!G70 -> 62276876 | H4: =G4*E4*D4 -> 62276876 | I4: =H4*$M$2 -> 62276876 | J4: =I4/$M$5 -> 662519.96 | K4: Conveyors | L4: Region | M4: Europe
A5: 4 | B5: Destinations | D5: 1 | E5: 1 | F5: Set | G5: =+Destinations!G23 -> 37678623 | H5: =G5*E5*D5 -> 37678623 | I5: =H5*$M$2 -> 37678623 | J5: =I5/$M$5 -> 400836.41 | K5: Destinations | L5: EURO | M5: 94 | N5: current rate is 100
A6: 5 | B6: Steelwork | D6: 1 | E6: 1 | F6: Set | G6: =+Steelworks!G10 -> 59135600 | H6: =G6*E6*D6 -> 59135600 | I6: =H6*$M$2 -> 59135600 | J6: =I6/$M$5 -> 629102.13 | K6: Steelworks
B7: CE Compliance | D7: 1 | E7: 1 | F7: Set | G7: ='Safety Cost Calc'!$D$19*2 -> 1040800 | H7: =(G7*E7*D7)/$M$1 -> 1541925.9 | I7: =H7*$M$2 -> 1541925.9 | J7: =I7/$M$5 -> 16403.467 | K7: CE Compliance
A8: 8 | B8: Software Packages | D8: 1 | E8: 1 | F8: Set | G8: =+'Software Packages'!F7 -> 1500000 | H8: =G8*E8*D8 -> 1500000 | I8: =H8*$M$2 -> 1500000 | J8: =I8/$M$5 -> 15957.447 | K8: Software
A9: 9 | B9: Installation & Commissioning | D9: 1 | E9: 1 | F9: Set | G9: ='Local I&C'!F10+'FAPL I&C'!D28 -> 51485880 | H9: =G9*E9*D9 -> 51485880 | I9: =H9*$M$2 -> 51485880 | J9: =I9/$M$5 -> 547722.13 | K9: Installation & Commissioning
A10: 10 | B10: Packaging & Documentation | D10: 1 | E10: 1 | F10: Set | G10: =SUM(H2:H6,)*5% -> 14964154 | H10: =G10*E10*D10 -> 14964154 | I10: =H10*$M$2 -> 14964154 | J10: =I10/$M$5 -> 159193.13 | K10: Packaging & Forwarding
A11: 11 | B11: Project Management and Engineering Charges | D11: 1 | E11: 1 | F11: Set | G11: =SUM(H2:H10)*2.5% -> 9219376 | H11: =G11*E11*D11 -> 9219376 | I11: =H11*$M$2 -> 9219376 | J11: =I11/$M$5 -> 98078.468 | K11: Project Management and Engineering Charges
A12: 12 | B12: System Acceptance Test | D12: 1 | E12: 1 | F12: Set | G12: ='FAPL SAT'!D28 -> 4195800 | H12: =G12*E12*D12 -> 4195800 | I12: =H12*$M$2 -> 4195800 | J12: =I12/$M$5 -> 44636.17
A13: 13 | B13: Freight | D13: 1 | E13: 1 | F13: Set | G13: ='I&C Cost'!J7 -> 19227273 | H13: =G13*E13*D13 -> 19227273 | I13: =H13*$M$2 -> 19227273 | J13: =I13/$M$5 -> 204545.45
A14: 14 | B14: Support Ramp Up | D14: 1 | E14: 1 | F14: Set | G14: ='Support Rampup'!D28 -> 1146600 | H14: =G14*E14*D14 -> 1146600 | I14: =H14*$M$2 -> 1146600 | J14: =I14/$M$5 -> 12197.872
A15: 15 | B15: Spare Kit | D15: 1 | E15: 1 | F15: Set | G15: =SUM(G2:G5)*2.5% -> 6003687 | H15: =G15*E15*D15 -> 6003687 | I15: =H15*$M$2 -> 6003687 | J15: =I15/$M$5 -> 63869.011
A16: 16 | B16: Protection on Ground | D16: 1 | E16: 1 | F16: Set | G16: 1500000 | H16: =G16*E16*D16 -> 1500000 | I16: =H16*$M$2 -> 1500000 | J16: =I16/$M$5 -> 15957.447
G17: Total | H17: =SUM(H2:H11) -> 3.7799442e+08 | I17: =SUM(I2:I12) -> 3.8219022e+08 | J17: =SUM(J2:J16) -> 4362423.2
H19: Recommended Spare Package | I19: =SUM(I2:I5)*8% -> 19211798 | J19: =SUM(J2:J5)*8% -> 204380.84

Sheet Safety Cost Calc
B3: Compliance Requirement | D3: CE/AS/NZS Compliance
B4: Type of Sorter | D4: CBS
B5: E-Stop Feedback | D5: Individual E-Stop
B6: Sorter Safety Component Costing
B7: Sr No. | C7: Section | D7: Qty | E7: UoM | F7: Remarks
B9: 1 | C9: Manual Feed Zone | D9: 2 | E9: No. | F9: considered 01 safety zone per each manual feeding zone
B10: 2 | C10: Auto Feedline | D10: 0 | E10: No. | F10: considered 01 safety zone per each auto feedline
B11: 3 | C11: CBS loop/Arm Sorter/SWEDI Sorter/POP-up Sorter | D11: 1 | E11: No. | F11: considered 01 safety zone per each CBS Loop CBS Safety zone serves as Global Stop (entire system stop)
B12: 4 | C12: Inbound Zone | D12: 2 | E12: No. | F12: considered 01 safety zone per each inbound zone
B13: 5 | C13: Highway | D13: 0 | E13: No. | F13: considered 01 safety zone per each Highway
B14: 6 | C14: VDS Loop | D14: 2 | E14: No. | F14: considered 01 safety zone per each VDS Loop
B15: 7 | C15: Outbound Zone | D15: 2 | E15: No. | F15: considered 01 safety zone per each outbound Zone
B16: 8 | C16: Maintenance Zone/Sorter Access | D16: 2 | E16: No. | F16: considered 01 safety zone per each outbound Zone
B17: 9 | C17: Pull Cord | D17: 2 | E17: No. | F17: Avg lenght 30 mtr
C19: Costing | D19: =Data!N25 -> 520400 | E19: INR | F19: Costing includes only material cost

Sheet Data
B2: Unit safety Zone Panel Cost | I2: Number of Zones
B3: Sr No. | C3: Component | D3: Qty | E3: Cost | F3: Total Cost | G3: Remarks | I3: Sr No. | J3: Section | K3: Qty | L3: UoM | M3: No. of Zones | N3: Zone Cost | O3: Remarks
B5: 1 | C5: Safety Controller | D5: 1 | E5: 15000 | F5: =D5*E5 -> 15000 | G5: Controller with 04 Test signal and 04 safety Outputs for 02 safety Zones | I5: 1 | J5: Manual Feedline | K5: ='Safety Cost Calc'!D9 -> 2 | L5: No. | M5: =K5*1 -> 2 | N5: =(M5/2)*$D$30 -> 84600
B6: 2 | C6: Contactors | D6: 4 | E6: 1500 | F6: =D6*E6 -> 6000 | G6: 04 contactor for 02 dual chanel output isolation | I6: 2 | J6: Auto Feedline | K6: ='Safety Cost Calc'!D10 -> 0 | L6: No. | M6: =K6*1 -> 0 | N6: =(M6/2)*$D$30 -> 0
B7: 3 | C7: Panel | D7: 1 | E7: 8000 | F7: =D7*E7 -> 8000 | I7: 3 | J7: ='Safety Cost Calc'!C11 -> CBS loop/Arm Sorter/SWEDI Sorter/POP-up Sorter | K7: ='Safety Cost Calc'!D11 -> 1 | L7: No. | M7: =K7*1 -> 1 | N7: =(M7/2)*$D$30 -> 42300
B8: 4 | C8: Cables | D8: 1 | E8: 10000 | F8: =D8*E8 -> 10000 | I8: 4 | J8: Inbound Zone | K8: ='Safety Cost Calc'!D12 -> 2 | L8: No. | M8: =K8*1 -> 2 | N8: =(M8/2)*$D$30 -> 84600
B9: 5 | C9: Switchgear | D9: 1 | E9: 2000 | F9: =D9*E9 -> 2000 | I9: 5 | J9: Highway | K9: ='Safety Cost Calc'!D13 -> 0 | L9: No. | M9: =K9*1 -> 0 | N9: =(M9/2)*$D$30 -> 0
B10: 6 | C10: SMPS | D10: 1 | E10: 7000 | F10: =D10*E10 -> 7000 | I10: 6 | J10: VDS Loop | K10: ='Safety Cost Calc'!D14 -> 2 | L10: No. | M10: =K10*1 -> 2 | N10: =(M10/2)*$D$30 -> 84600
B11: 7 | C11: E-Stop+mounting | D11: 8 | E11: 2700 | F11: =D11*E11 -> 21600 | G11: 04 E-stops considered for each safety zone | I11: 7 | J11: Outbound Zone | K11: ='Safety Cost Calc'!D15 -> 2 | L11: No. | M11: =K11*1 -> 2 | N11: =(M11/2)*$D$30 -> 84600
F12: =SUM(F5:F11) -> 69600 | I12: 8 | J12: Maintenance Zone/Sorter Access | K12: ='Safety Cost Calc'!D16 -> 2 | L12: No. | M12: NA | N12: =K12*$F$20 -> 36000
B13: 8 | C13: Murr Card for feedback+cabling | D13: 0.5 | E13: 30000 | F13: =D13*E13 -> 15000 | G13: 01 card per 16 E-Stop inputs | I13: 9 | J13: =C21 -> Inching Station (Mech+Elec) | K13: =IF('Safety Cost Calc'!D4=Data!J22,0,Data!K7) -> 1 | L13: No. | M13: NA | N13: =(K13*F21) -> 9300
F14: =F12+F13 -> 84600 | I14: 10 | J14: =C22 -> Pull Cord | K14: ='Safety Cost Calc'!D17 -> 2 | L14: No. | M14: NA | N14: =K14*F22 -> 18400
B15: Safety Components Costing | I15: 11 | J15: =C18 -> Speed Monitoring Controller (SMC) | K15: =IF('Safety Cost Calc'!D4=Data!J22,0,Data!K7) -> 1 | L15: No. | M15: NA | N15: =K15*(F18+F19) -> 76000
B16: Sr No. | C16: Component | D16: Qty | E16: Cost | F16: Total Cost
B18: 1 | C18: Speed Monitoring Controller (SMC) | D18: 1 | E18: 60000 | F18: =E18*D18 -> 60000 | G18: For Sorter Dead speed and safe speed monitoring
B19: 2 | C19: SMC Photo sensors + Cables | D19: 2 | E19: 8000 | F19: =E19*D19 -> 16000 | G19: For Sorter Dead speed and safe speed monitoring | J19: Compliance | N19: Cost
B20: 3 | C20: Safety Door Switches | D20: 1 | E20: 18000 | F20: =E20*D20 -> 18000 | J20: CE/AS/NZS Compliance | N20: =(SUM(N5:N15)) -> 520400
B21: 4 | C21: Inching Station (Mech+Elec) | D21: 1 | E21: =5000+4300 -> 9300 | F21: =E21*D21 -> 9300 | G21: For inching mode | J21: STD Compliance | N21: =SUM(N5:N14) -> 444400
B22: 5 | C22: Pull Cord | D22: 1 | E22: 9200 | F22: =E22*D22 -> 9200 | G22: Avg length 30 mtrs | J22: Non CBS | N22: =SUM(N5:N12)+N14 -> 435100
N25: =IF('Safety Cost Calc'!D4=Data!J22,Data!N22,IF('Safety Cost Calc'!D3=Data!J20,Data!N20,Data!N21)) -> 520400
C27: Safety Door Switches
C28: CBS
C29: Non CBS
C30: FeedBack of | D30: =IF('Safety Cost Calc'!D5=Data!C31,Data!D31,Data!D32) -> 84600
C31: Individual Zone | D31: =F12 -> 69600
C32: Individual E-Stop | D32: =F14 -> 84600

Sheet Section Identification
A3: Sr No. | B3: Section
A5: 1 | B5: Manual Feed Zone
A6: 2 | B6: Auto Feedline
A7: 3 | B7: CBS loop/Arm Sorter/SWEDI Sorter/POP-up Sorter
A8: 4 | B8: Inbound Zone
A9: 5 | B9: Highway
A10: 6 | B10: VDS Loop
A11: 7 | B11: Outbound Zone
A12: 8 | B12: Maintenance Zone/Sorter Access
A13: 9 | B13: Pull Cord

Sheet Loop CBS
B1: Factor | C1: ='Overall Costing'!$M$1 -> 0.675 | D1: Speed Factor | E1: 1.1
A3: Model Number Understanding->> | B3: CB-[Single/Dual Belt]-[Carrier Pitch]-[Belt Length]
A4: Model Number | B4: Carrier Type | C4: Carrier Pitch | D4: Carrier Belt- Belt Pitch/Length (mm) | E4: Curve Radius (m) | F4: LIM Compatible? | G4: LSM Compatible? | H4: Belts Per Carrier | I4: Belts per LIM | J4: Belts per LSM
A5: CB-SB-600-800 | B5: Single Belt | C5: 600 | D5: 600/800 | E5: 3.5 | F5: Yes | G5: Yes | H5: 1 | I5: 40 | J5: 60
A6: CB-DB-1175-800 | B6: Dual Belt | C6: 1175 | D6: 600/800 | E6: 4.5 | F6: Yes | G6: No | H6: 2 | I6: 40 | J6: NA
A7: XL-CB-DB-1200-1200 | B7: XL- Dual Belt | C7: 1200 | D7: 600/1200 | E7: 4.58 | F7: Yes | G7: Yes | H7: 2 | I7: 32 | J7: 36
A8: XL-CB-SB-800-1200 | B8: XL- Single Belt | C8: 800 | D8: 800/1200 | E8: 4.58 | F8: Yes | G8: Yes | H8: 1 | I8: 32 | J8: 36
A11: 1 | B11: Select Model | C11: CB-DB-1175-800
A12: Output | B12: Radius | C12: =VLOOKUP(C11,A4:G8,5,FALSE) -> 4.5
A13: Output | B13: Radius Price | C13: =VLOOKUP(C12,Loop!$C$4:$D$6,2,FALSE) -> 27466.436
A14: 2 | B14: Enter the Number of 30 Degree Curves | C14: =(16*45)/30 -> 24
A15: 3 | B15: Enter the Loop Length (Including length of Curves) in meters | C15: =(146.875*2)+(3.6*16) -> 351.35
A16: Output | B16: Curve Length (m) | C16: =C14*2*3.14*C12/12 -> 56.52
A17: Output | B17: Straight Track length (m) | C17: =C15-C16 -> 294.83
A18: Output | B18: Cost of Straight Track | C18: =IF(OR(C11=A5,C11=A6),C17*Loop!D2,C17*Loop!D3) -> 6445087
A19: Output | B19: Cost of Curved track | C19: =C13*C14 -> 659194.46
A20: Output | B20: Total Track Cost (A) | C20: =C19+C18 -> 7104281.4
A21: Output | B21: Carrier Pitch | C21: =VLOOKUP(C11,A4:G8,3,FALSE) -> 1175
A22: Output | B22: Carrier Unit Price | C22: =VLOOKUP(C21,Loop!C7:D10,2,FALSE) -> 14796.02
A23: Output | B23: Number of Carriers | C23: =ROUND(C15*1000/C21,0) -> 299
A24: Output | B24: Total Carrier Cost (B) | C24: =C23*C22 -> 4424010
A25: Output | B25: Belts per Carrier | C25: =VLOOKUP(C11,A4:H8,8,FALSE) -> 2
A26: Output | B26: Total Carrier Belts | C26: =C23*C25 -> 598
A27: Output | B27: Carrier Belt Type | C27: =VLOOKUP(C11,A4:H8,4,FALSE) -> 600/800
A28: Output | B28: Carrier Belt Unit Price | C28: =VLOOKUP(C27,Loop!C12:D14,2,FALSE) -> 30378.6
A29: Output | B29: Total Carrier Belt Cost (C) | C29: =C28*C26 -> 18166403
A30: 4 | B30: Select the Sorter Height | C30: >2.4 meter and <=3.5 meter | D30: 3.1m
A31: Output | B31: Unit Price per Leg | C31: =VLOOKUP(C30,Loop!C16:D18,2,FALSE) -> 15584.8
A32: Output | B32: Number of Legs | C32: =ROUNDUP(C15/2.4,0) -> 147
A33: Output | B33: Total Legs Cost (D) | C33: =C32*C31 -> 2290965.6
A34: 5 | B34: Select Type of Linear Motor | C34: LIM
A35: Output | B35: Number of Belts Per Motor | C35: =IF(C34="LSM",VLOOKUP(C11,A4:J8,10,FALSE),VLOOKUP(C11,A4:J8,9,FALSE)) -> 40
A36: Output | B36: Total Number of Motors | C36: =ROUNDUP(C26/C35,0) -> 15
A37: Output | B37: Unit Price per Motor Drive | C37: =VLOOKUP(C34,Loop!C20:D21,2,FALSE) -> 364930.65
A38: Output | B38: Total Drive cost (E) | C38: =C36*C37 -> 5473959.8
A39: Output | B39: Total Loop Control Cost (F) | C39: =IF(OR(C11=A5,C11=A6),Loop!D23,Loop!D24) -> 432669.44
A40: 6 | B40: Select the PLC Platform | C40: Siemens
A41: Output | B41: Total PLC Platform Cost (G) | C41: =VLOOKUP(C40,Loop!C25:D26,2,FALSE) -> 4015547.1
A42: 7 | B42: Server Required? | C42: No
A43: 8 | B43: If Yes, Select the Server Configuration | C43: HAA-Falcon Standard
...

Sheet Inducts
B2: Conveyor Name | C2: Width | D2: <10 mm | E2: >=10 mm | F2: Length
B3: Angle Merge | C3: 800 | D3: =120170*1.125 -> 135191.25 | E3: =120170*1.125 -> 135191.25 | F3: 2
B4: Angle Merge | C4: 1000 | D4: =D3*1.1 -> 148710.38 | E4: =E3*1.1 -> 148710.38 | F4: 3
B5: Angle Merge XL | C5: 1000 XL | D5: =D4*1.1 -> 163581.41 | E5: =E4*1.1 -> 163581.41 | F5: 3
B6: Angle Merge | C6: 1200 | D6: =D4*1.2 -> 178452.45 | E6: =E4*1.2 -> 178452.45 | F6: 3
B7: Buffer Conveyor | C7: 800 | D7: =101317*1.125 -> 113981.62 | E7: =D7-24000+4000 -> 93981.625 | F7: 1
B8: Buffer Conveyor | C8: 1000 | D8: =D7*1.1 -> 125379.79 | E8: =E7*1.1 -> 103379.79 | F8: 1
B9: Buffer Conveyor XL | C9: 1000 XL | D9: - | E9: =E8*1.1 -> 113717.77 | F9: 0.5
B10: Buffer Conveyor | C10: 1200 | D10: =D8*1.2 -> 150455.74 | E10: =E8*1.2 -> 124055.74 | F10: =F8 -> 1
B11: Spacing Conveyor | C11: 800 | D11: =105817*1.125 -> 119044.12 | E11: =D11-24000+4000 -> 99044.125 | F11: 1
B12: Spacing Conveyor | C12: 1000 | D12: =D11*1.1 -> 130948.54 | E12: =E11*1.1 -> 108948.54 | F12: 1.5
B13: Spacing Conveyor XL | C13: 1000 XL | D13: - | E13: =E12*1.1 -> 119843.39 | F13: 1.2
B14: Spacing Conveyor | C14: 1200 | D14: =D12*1.2 -> 157138.24 | E14: =E12*1.2 -> 130738.24 | F14: =F12 -> 1.5
B15: Single Operator Loading Conveyor | C15: 800 | D15: =E15+24000-4000 -> 169002.88 | E15: =132447*1.125 -> 149002.88 | F15: 1.5
B16: Single Operator Loading Conveyor | C16: 1000 | D16: =D15*1.1 -> 185903.16 | E16: =E15*1.1 -> 163903.16 | F16: 1.5
B17: Single Operator Loading Conveyor XL | C17: 1000 XL | D17: - | E17: =E16*1.1 -> 180293.48 | F17: =F16 -> 1.5
B18: Single Operator Loading Conveyor | C18: 1200 | D18: =D16*1.2 -> 223083.8 | E18: =E16*1.2 -> 196683.8 | F18: =F16 -> 1.5
B19: Double Operator Loading Conveyor | C19: 800 | D19: =E19+24000-4000 -> 284375 | E19: =235000*1.125 -> 264375 | F19: 3.5
B20: Double Operator Loading Conveyor | C20: 1000 | D20: =D19*1.1 -> 312812.5 | E20: =E19*1.1 -> 290812.5 | F20: 5
B21: Double Operator Loading Conveyor XL | C21: 1000 XL | D21: - | E21: =E20*1.1 -> 319893.75 | F21: =F20 -> 5
B22: Double Operator Loading Conveyor | C22: 1200 | D22: =D20*1.2 -> 375375 | E22: =E20*1.2 -> 348975 | F22: =F20 -> 5
B23: Receiving Conveyor | C23: 800 | D23: =E23+24000-4000 -> 284375 | E23: =235000*1.125 -> 264375 | F23: 3.5
B24: Receiving Conveyor | C24: 1000 | D24: =D23*1.1 -> 312812.5 | E24: =E23*1.1 -> 290812.5 | F24: 5
B25: Receiving Conveyor XL | C25: 1000 XL | D25: - | E25: =E24*1 -> 290812.5 | F25: 3.3
B26: Receiving Conveyor | C26: 1200 | D26: =D24*1.2 -> 375375 | E26: =E24*1.2 -> 348975 | F26: =F24 -> 5
B27: Top Loader Induct | C27: 800 | D27: 130948.54 | E27: 108948.54 | F27: 1
C29: Control Panel | D29: =198000*1.12 -> 221760
C30: Leg Structure | D30: =(75000/6)*1.15 -> 14375
C31: Overshoot Assembly | D31: =14000*1.15 -> 16100
C40: 13

Sheet Linear CBS
B1: Factor | C1: ='Overall Costing'!$M$1 -> 0.675
A3: Model Number Understanding->> | B3: CB-[Single/Dual Belt]-[Carrier Pitch]-[Belt Length]
A4: Model Number | B4: Carrier Type | C4: Carrier Pitch | D4: Carrier Belt- Belt Pitch/Length (mm) | E4: Curve Radius (m) | F4: LIM Compatible? | G4: LSM Compatible? | H4: Belts Per Carrier | I4: Belts per LIM | J4: Belts per LSM
A5: CB-SB-500-800 | B5: Single Belt | C5: 500 | D5: 500/800 | E5: NA | F5: Yes | G5: Yes | H5: 1 | I5: 20 | J5: =VLOOKUP($C$8,Linear!$C$2:$E$3,3,0) -> 30
A8: 1 | B8: Select Model | C8: Heavy Duty | D8: Regular<=10 Kg for Sigle Carrier
A9: 2 | B9: Enter Linear Length (Top side only excluding curves) in meters | C9: 20.08
A10: Output | B10: Straight Track length (m) | C10: =+C9*2 -> 40.16
A11: Output | B11: Cost of Straight Track | C11: =(VLOOKUP($C$8,Linear!C2:$D$3,2,0))*C10 -> 1465840
A12: Output | B12: Cost of Curved track | C12: =+Linear!D4 -> 76500
A13: Output | B13: Total Track Cost (A) | C13: =C12+C11 -> 1542340
A14: Output | B14: Carrier Unit Price | C14: =VLOOKUP($C$8,Linear!$C$7:$D$8,2,0) -> 41500
A15: Output | B15: Number of Carriers | C15: =ROUNDUP((C9*1000/C5)*2+8,0) -> 89
A16: Output | B16: Total Carrier Cost (B) | C16: =C15*C14 -> 3693500
A17: Output | B17: Unit Price per Leg | C17: =Linear!$D$10 -> 8000 | D17: Standard
A18: Output | B18: Number of Legs | C18: =ROUNDUP(C9/2.4,0) -> 9
A19: Output | B19: Total Legs Cost (C) | C19: =C18*C17 -> 72000
A20: 3 | B20: Select Type of Linear Motor | C20: LSM
A21: Output | B21: Number of Belts Per Motor | C21: =IF(C20="LSM",$J$5,IF(C20="LIM",$I$5,0)) -> 30 | D21: Standard LSM
A22: Output | B22: Total Number of Motors | C22: =ROUNDUP(C15/C21,0) -> 3
A23: Output | B23: Unit Price per Motor Drive | C23: =VLOOKUP(C20,Linear!C12:D13,2,FALSE) -> 681000 | F23: ;
A24: Output | B24: Total Drive cost (D) | C24: =C22*C23 -> 2043000
A25: Output | B25: Positionning & Centering Cost (E) | C25: =Linear!D15 -> 333987.56
A26: 4 | B26: Select the PLC Platform & Controle | C26: Omron
A27: Output | B27: Loop Controle | C27: =VLOOKUP($C$26,Linear!$C$16:$D$17,2,0) -> 250000
A28: Output | B28: Main Controle (PLC Platform) | C28: =VLOOKUP($C$26,Linear!$C$19:$D$20,2,0) -> 1400000
A29: Output | B29: Total PLC Platform Cost (F) | C29: =C27+C28 -> 1650000
A30: 5 | B30: Server Required? | C30: YES | D30: NO for International Projects
A31: 6 | B31: If Yes, Select the Server Configuration | C31: HAA-Amazon Standard
A32: Output | B32: Unit Price of Selected Server | C32: =IF(C30="Yes",VLOOKUP(C31,Linear!C22:D23,2,FALSE),0) -> 2128000
A33: Output | B33: Total Server Price (G) | C33: =C32 -> 2128000
A34: 7 | B34: Enter Number of Induct Zones | C34: 0
A35: 8 | B35: Scanning tunnel Qty/ induct zone | C35: 0
A36: 9 | B36: ICR-890 12K | C36: =VLOOKUP(B36,Linear!$C$25:$D$31,2,0) -> 1880402.9
A37: Output | B37: Total Barcode Scanning Cost | C37: =C36*C35*C34 -> 0
A38: 10 | B38: VMS Qty/ induct zone | C38: 0
A39: 11 | B39: VMS 4200 | C39: =VLOOKUP(B39,Linear!$C$32:$D$34,2,0) -> 825000
A40: Output | B40: Total Volume Scanning Cost | C40: =C39*C38*C34 -> 0
A41: Output | B41: Total Scan Tunnel Costs (H) | C41: =C40+C37 -> 0
A42: 12 | B42: Select Minimum Height of Product | C42: >=10 mm
A43: 13 | B43: Length of Wiremesh Fencing (in meters)
...

Sheet Budgetary Costing
B1: Region | C1: Middle East | H1: Sales Factor | I1: 0.6
B2: Item | C2: Qty | D2: UOM | E2: Set | F2: Unit Price | G2: Total Price
B3: NEO Bots | C3: 0 | D3: Nos | E3: 1 | F3: =HLOOKUP($C$1,'NEO New rate data'!$C$2:$E$3,2,0) -> 1396551.7 | G3: =F3*E3*C3 -> 0
B4: Spare battery | C4: =ROUNDUP(C3/3,0) -> 0 | D4: Nos | E4: 1 | F4: =HLOOKUP($C$1,'NEO New rate data'!$C$2:$E$4,3,0) -> 89655.172 | G4: =F4*E4*C4 -> 0
B5: GTC Station | C5: 0 | D5: Nos | E5: 1 | F5: =HLOOKUP($C$1,'NEO New rate data'!$C$2:$E$5,4,0) -> 1370689.7 | G5: =F5*E5*C5 -> 0
B6: GTP Station | C6: 0 | D6: Nos | E6: 1 | F6: =HLOOKUP($C$1,'NEO New rate data'!$C$2:$E$6,5,0) -> 775862.07 | G6: =F6*E6*C6 -> 0 | L6: Partition
B7: Bin Position Cost | C7: 0 | D7: Nos | E7: 1 | F7: =HLOOKUP($C$1,'NEO New rate data'!$C$2:$E$7,6,0) -> 3666.6667 | G7: =F7*E7*C7 -> 0
A8: Bin Type | B8: Six Compartment Bin | C8: =C7 -> 0 | D8: Nos | E8: 1 | F8: =INDEX('NEO New rate data'!$C$9:$E$13,MATCH('Budgetary Costing'!B8,'NEO New rate data'!$B$9:$B$13,0),MATCH('Budgetary Costing'!C1,'NEO New rate data'!C2:E2,0)) -> 1437.5 | G8: =F8*E8*C8 -> 0
B9: Short Side Partition | C9: =VLOOKUP($B$8,'NEO New rate data'!$B$9:$H$13,6,0) -> 2 | D9: Nos | E9: 1 | F9: =HLOOKUP($C$1,'NEO New rate data'!$C$2:$E$14,13,0) -> 50 | G9: =F9*E9*C9*C7 -> 0
B10: Long Side Partition | C10: =VLOOKUP($B$8,'NEO New rate data'!$B$9:$H$13,7,0) -> 1 | D10: Nos | E10: 1 | F10: =HLOOKUP($C$1,'NEO New rate data'!$C$2:$E$15,14,0) -> 71.428571 | G10: =F10*E10*C10*C7 -> 0
B11: Charging Station | C11: 0 | D11: Set | E11: 1 | F11: =HLOOKUP($C$1,'NEO New rate data'!$C$2:$E$16,15,0) -> 926724.14 | G11: =F11*E11*C11 -> 0
B12: IT Server and IT Infra | C12: 1 | D12: Set | E12: 1 | F12: =HLOOKUP($C$1,'NEO New rate data'!$C$2:$E$17,16,0) -> 2672413.8 | G12: =F12*E12*C12 -> 2672413.8
B13: Mechanical and Electrical Infra | C13: 1 | D13: Set | E13: 1 | F13: =(SUM(G3:G12))*4% -> 106896.55 | G13: =F13*E13*C13 -> 106896.55
B14: WCS Cost | C14: 1 | D14: Set | E14: 1 | F14: =HLOOKUP($C$1,'NEO New rate data'!$C$2:$E$19,18,0) -> 2500000 | G14: =F14*E14*C14 -> 2500000
B15: WCS Annual License | C15: 1 | D15: Set | E15: 1 | F15: =HLOOKUP($C$1,'NEO New rate data'!$C$2:$E$20,19,0) -> 250000 | G15: =F15*E15*C15 -> 250000
B16: IT Integration | C16: 1 | D16: Set | E16: 1 | G16: =F16*E16*C16 -> 0 | H16: As per the Scope of Customization and Integration effort
B17: Safety Architecture | C17: 1 | D17: Set | E17: 1 | F17: 400000 | G17: =(F17/I1)*E17*C17 -> 666666.67
B18: Packing and Forwarding | C18: 1 | D18: Set | E18: 1 | F18: =(HLOOKUP($C$1,'NEO New rate data'!$C$2:$E$23,22,0))*SUM(G3:G13) -> 138965.52 | G18: =F18*E18*C18 -> 138965.52
B19: Freight | C19: 1 | D19: Set | E19: 1 | G19: =F19*E19*C19 -> 0 | H19: As per Site Location and BOM
B20: Installation and Commissioning | C20: 1 | D20: Set | E20: 1 | F20: =(HLOOKUP($C$1,'NEO New rate data'!$C$2:$E$25,24,0))*(G3+G4+G5+G6+G7+G11+G12+G13) -> 0 | G20: =F20*E20*C20 -> 0 | H20: To be estimated as per Country/State and Size of the System
B21: Project Management | C21: 1 | D21: Set | E21: 1 | F21: =(HLOOKUP($C$1,'NEO New rate data'!$C$2:$E$22,21,0))*SUM(G3:G20) -> 190048.28 | G21: =F21*E21*C21 -> 190048.28
B22: Grand Total | G22: =SUM(G3:G21) -> 6524990.8

Sheet NEO New rate data
A1: NEO New Rate Card | C1: Quote Price (INR)
A2: S.No | B2: Item | C2: India | D2: ANZ and EU | E2: Middle East
A3: 1 | B3: NEO Bot | C3: 1350000 | D3: 1620000 | E3: 1396551.7
A4: 2 | B4: Spare battery | C4: 86666.667 | D4: 104000 | E4: 89655.172 | F4: Generally Quoted 1 for every 3 Bots
A5: 3 | B5: GTC Station | C5: 1325000 | D5: 1590000 | E5: 1370689.7 | F5: This is Standard GTC Station including Bin Conveyors + Bin Scanners + Touch Screen Operator Panel + Fixed Mounted Scanner for SKU Scanning + Canopy
A6: 4 | B6: GTP Station | C6: 750000 | D6: 900000 | E6: 775862.07 | F6: This is Standard GTP Station including Touch Screen Operator Panel + Fixed Mounted Scanner for SKU Scanning + Canopy
A7: 5 | B7: Bin Position Cost | C7: 3473.6842 | D7: 3882.3529 | E7: 3666.6667 | F7: Includes the Cost of Racking + Teeth Rack + Tracks
A8: 6 | B8: Plastic Bin Cost | G8: Sort side partition | H8: Long side partition
A9: a | B9: Single Compartment Bin | C9: 1017.6471 | D9: 1081.25 | E9: 1081.25 | G9: 0 | H9: 0 | I9: Single Compartment Bin
A10: b | B10: Two Compartment Bin | C10: 1122.3529 | D10: 1192.5 | E10: 1192.5 | G10: 1 | H10: 0 | I10: Two Compartment Bin
A11: c | B11: Three Compartment Bin | C11: 1227.0588 | D11: 1303.75 | E11: 1303.75 | G11: 3 | H11: 0 | I11: Three Compartment Bin
A12: d | B12: Four Compartment Bin | C12: 1247.0588 | D12: 1325 | E12: 1325 | G12: 1 | H12: 1 | I12: Four Compartment Bin
A13: e | B13: Six Compartment Bin | C13: 1352.9412 | D13: 1437.5 | E13: 1437.5 | G13: 2 | H13: 1 | I13: Six Compartment Bin
A14: 7 | B14: Short Side Partition | C14: 43.75 | D14: 50 | E14: 50
A15: 8 | B15: Long Side Partition | C15: 62.5 | D15: 71.428571 | E15: 71.428571
A16: 9 | B16: Charging Station | C16: 895833.33 | D16: 1075000 | E16: 926724.14
A17: 10 | B17: IT Server and IT Infra | C17: 2583333.3 | D17: 3100000 | E17: 2672413.8
A18: 11 | B18: Mechanical and Electrical Infra (% of the equipment Sales Value) | C18: 0.04 | D18: 0.04 | E18: 0.04 | F18: Including - Fencing Mechanical + Electrical - Power Distribution Panels - Control Panels and Field Devices - Distribution Panels and Field Devices - Misc Consumables
A19: 12 | B19: WCS Cost | C19: 1500000 | D19: 2500000 | E19: 2500000 | F19: WCS License and Setup up cost
A20: 13 | B20: WCS Annual License | D20: =D19*0.1 -> 250000 | E20: =E19*0.1 -> 250000 | F20: Annual License Renewal
A21: 14 | B21: IT Integration | C21: Variable | D21: Variable | E21: Variable | F21: As per the Scope of Customization and Integration effort
A22: 15 | B22: Project Management (of Equipment Price) | C22: 0.025 | D22: 0.03 | E22: 0.03
A23: 16 | B23: Packing and Forwarding (of Equipment Price) | C23: 0.02 | D23: 0.05 | E23: 0.05
A24: 17 | B24: Freight | C24: Variable | D24: Variable | E24: Variable | F24: As per Site Location and BOM
A25: 18 | B25: Installation and Commissioning (of Equipment Price excluding Bins) | C25: 0.05 | D25: 0 | E25: 0 | F25: To be estimated as per Country/State and Size of the System

Sheet Linear
C1: Specs | D1: Unit Price | E1: Belt/motor | G1: YES
B2: Sorter track | C2: Regular | D2: ='Final Rate card'!$C$7 -> 32500 | E2: 40 | G2: No
C3: Heavy Duty | D3: ='Final Rate card'!$C$8 -> 36500 | E3: 30
B4: Curves | C4: 360 Deg Curves | D4: ='Final Rate card'!$C$9 -> 76500 | E4: Cost is for 360deg curve /per count
B7: Carrier | C7: Regular | D7: ='Final Rate card'!$C$2+'Final Rate card'!$C$3 -> 39123
C8: Heavy Duty | D8: ='Final Rate card'!$C$2+'Final Rate card'!$C$4 -> 41500
B10: Leg Cost | C10: 1.7 meter height | D10: ='Final Rate card'!$C$10 -> 8000
B12: Linear Motor Drive Set | C12: LIM | D12: 250000
C13: LSM | D13: ='Final Rate card'!C5 -> 681000
B15: Positioning & Centering | D15: 333987.56
B16: Sorter Loop Control | C16: Omron | D16: ='Final Rate card'!$C$11 -> 250000
C17: Siemens | D17: ='Final Rate card'!$C$13 -> 600000
B19: PLC Platform | C19: Omron | D19: ='Final Rate card'!$C$12 -> 1400000
C20: Siemens | D20: ='Final Rate card'!$C$14 -> 3700000
B22: Server Setup | C22: HAA-Falcon Standard | D22: =(764700+186000)*1.12 -> 1064784
C23: HAA-Amazon Standard | D23: =1900000*1.12 -> 2128000
B25: Barcode Scanning Tunnel | C25: ICR-890 8K | D25: =1527639*1.1 -> 1680402.9
C26: ICR-890 12K | D26: =+(1527639*1.1)+200000 -> 1880402.9
C27: ICR890 12K 3 Camera- 3/5 Side Per Scan Tunnel | D27: 3200000
C28: ICR890 12K 5 Camera- 5 Side Per Scan Tunnel | D28: ='Quote Master'!$H$109 -> 5800000
C29: Cognex 3 Camera- Top scan without Image Capturing Per Scan Tunnel | D29: 110000
C30: COGENAX Top side scanning (DM3816X) | D30: ='Quote Master'!$H$110 -> 424771
C31: Cognex 3 Camera- Top scan with Image Capturing Per Scan Tunnel | D31: 1350000
B32: VMS | C32: VMS 4200 | D32: =750000*1.1 -> 825000
C33: VMS5200 | D33: =950000*1.1 -> 1045000
C34: COGNEX VMS (3D- A1000) | D34: ='Quote Master'!$H$113 -> 351032
B38: Safety Net | C38: Per meter | D38: =7656*1.15 -> 8804.4
B39: Fencing | C39: Per meter | D39: =6590*1.15 -> 7578.5
B40: Bridge Plate | C40: Per meter | D40: =3685*1.15 -> 4237.75

Sheet Final Rate card
A1: S.NO | B1: Item | C1: Final Rate card | D1: Specs/Remarks
A2: 1 | B2: Chasis | C2: 15900 | D2: 4 X Blickle 2 X Bharat LSM Magnet Wheel Mounting for Blickel
A3: 2 | B3: Carrier- Regular | C3: 23223 | D3: Bellow Added Sheet Thickness Increased Node Plates are here (Omron or Siemens) Includes CBS Power plate with Meanwell DC converter and Schneider MCB Includes Connector & Communication cable Includes Carrier Position sensor and reflector unit Includes Harness Field | F3: =C2+C3 -> 39123
A4: 3 | B4: Carrier- Heavy Duty | C4: 25600 | D4: Bellow Added Sheet Thickness Increased Node Plates are here (Omron or Siemens) Includes CBS Power plate with Meanwell DC converter and Schneider MCB Includes Connector & Communication cable Includes Carrier Position sensor and reflector unit Includes Harness Field
A5: 4 | B5: Drive Unit- Regular | C5: 681000 | D5: SEW LSM (Linear Magnetic Motor, Inverter, encoder, Braking Resistor, encoder cables, Line Filter, Keypad, Line Choke & Output Choke), Gap Filler and drive unit accessories - One Motor Set for 40 Carriers Includes Linear Sorter LSM motor Junction box Includes Sorter Drive (LSM) Panel Includes Drive Panel (LSM) Field Material
A6: 5 | B6: Drive Unit- Heavy Duty | C6: 681000 | D6: SEW LSM (Linear Magnetic Motor, Inverter, encoder, Braking Resistor, encoder cables, Line Filter, Keypad, Line Choke & Output Choke) -One Motor Set for 30 Carriers Includes Linear Sorter LSM motor Junction box Includes Sorter Drive (LSM) Panel Includes Drive Panel (LSM) Field Material
A7: 6 | B7: Straight Track (per Meter)- Regular | C7: 32500 | D7: Length to be considered from Plan View Bus Bar elements and Leaky Wave is here Includes Linear Current Collector Includes Insulated Conductor & Compact hanger Includes Hooters for CBS Includes SMPS Panel and its accessoriers and SMPS panel Field material Includes Barcode Sensor & Barcode Tape Includes Sorter Cable tray
A8: 7 | B8: Straight Track (per Meter)- Heavy Duty | C8: 36500 | D8: Length to be considered from Plan View Bus Bar elements and Leaky Wave is here Includes Linear Current Collector Includes Insulated Conductor & Compact hanger Includes Hooters for CBS Includes SMPS Panel and its accessoriers and SMPS panel Field material Includes Barcode Sensor & Barcode Tape Includes Sorter Cable tray
A9: 8 | B9: Curev Track (per Count) | C9: 76500 | D9: This cost is for 360 Degree Curve. Consider 8 Carriers on the curve length Includes Tail & Drive end unit and Tail end block
A10: 9 | B10: Legs (per Leg) | C10: 8000 | D10: Consider one Leg per 2.4 meters
A11: 10 | B11: Loop Control- Omron | C11: 250000 | D11: Includes Speed calculation, pitch sensor & monitoring sensor (all three types) Includes Linear Sorter Field material
A12: 11 | B12: Main Control- Omron | C12: 1400000 | D12: Includes Control Panel, Remote panel, wifi Panel, Power distribution panel, Junction Box, Safety Relay/ Controller panel and field material for the same. Includes Sorter Scada Field material Includes Stickers, Panel stand and consumables
A13: 12 | B13: Loop Control- Siemens | C13: 600000 | D13: Includes Speed calculation, pitch sensor & monitoring sensor (all three types) Includes Linear Sorter Field material
A14: 13 | B14: Main Control- Siemens | C14: 3700000 | D14: Includes Control Panel, Remote panel, wifi Panel, Power distribution panel, Junction Box, Safety Relay/ Controller panel, Sorter Safety speed detection Panel and field material for the same. Includes Sorter Scada Field material Includes Stickers, Panel stand and consumables

Sheet Arm Sorter
A1: S.No. | B1: Description | C1: Quantity | D1: UOM | E1: Unit Price | F1: Total | G1: Sales Factor | H1: ='Overall Costing'!$M$1 -> 0.675
A2: 1 | B2: Sorter running length | C2: =(4.14+4.5+4.5+4.5+4.5+4.5+5.46)*2 -> 64.2 | D2: Meters | E2: =100000*2 -> 200000 | F2: =E2*C2 -> 12840000
A3: 2 | B3: Arm XL | C3: =7*2 -> 14 | D3: Nos | E3: =VLOOKUP(B3,'Quote Master'!$C$54:$I$55,7,0) -> 175000 | F3: =E3*C3 -> 2450000
A4: 3 | B4: ICR 890 12K | D4: Nos | E4: =VLOOKUP(B4,'Quote Master'!$C$107:$I$112,7,0) -> 3134004.8 | F4: =E4*C4 -> 0
A5: 4 | B5: VMS 5200 | D5: Nos | E5: =VLOOKUP(B5,'Quote Master'!$C$107:$I$112,7,0) -> 1741666.7 | F5: =E5*C5 -> 0
A6: 5 | B6: PLC based control | C6: =1*2 -> 2 | D6: Nos | E6: =+'Quote Master'!I102 -> 800000 | F6: =+E6*C6 -> 1600000
A7: 6 | B7: Server PC | D7: Nos | E7: =+'Quote Master'!I106 -> 250000 | F7: =E7*C7 -> 0
A8: 7 | B8: HAA Server | D8: Nos | E8: =+'Quote Master'!I103 -> 2121000 | F8: =E8*C8 -> 0
E9: Total | F9: =SUM(F2:F8) -> 16890000 | G9: =F9/'Overall Costing'!M5 -> 179680.85
B11: Induction line
A12: 8 | B12: Enter the Total Number of Inducts in the System | C12: 0
A13: 9 | B13: Width of Induct Conveyors | C13: 800 mm
A14: 10 | B14: Enter number of Launchpad conveyors | C14: 0
A15: 11 | B15: Enter Length of Launchpad conveyor(mm) | C15: 0
A16: 12 | B16: Enter number of Angle Merge Conveyors per Induct | C16: 0
A17: 13 | B17: Enter Number of Short Buffer Conveyors per Induct | C17: 0
A18: 14 | B18: Enter Number of Spacing Conveyors per Induct | C18: 0
A19: 15 | B19: Enter Number of Receiving Conveyor | C19: 0
A20: 16 | B20: Enter length of Receiving Conveyor(mm) | C20: 0
A22: Output | D22: Unit Price | E22: Total Price | F22: Length (for Cable Tray and Leg Calculation) | G22: Row | H22: Column
A23: Output | B23: Total Number of Angle Merge Conveyors | C23: =+C12*C16 -> 0 | D23: {=INDEX('Induct line for Arm'!D3:D4,'Arm Sorter'!G23,'Arm Sorter'!H23)} -> 148710.38 | E23: =C23*D23 -> 0 | F23: {=INDEX('Induct line for Arm'!F3:F4,G23,1)*C23} -> 0 | G23: =MATCH($C$13,'Induct line for Arm'!C3:C4,0) -> 2 | H23: 1
A24: Output | B24: Total Number of Short Buffer Conveyors | C24: =+C17*C12 -> 0 | D24: {=INDEX('Induct line for Arm'!D5:D6,'Arm Sorter'!G24,'Arm Sorter'!H24)} -> 125379.79 | E24: =C24*D24 -> 0 | F24: {=INDEX('Induct line for Arm'!F5:F6,G24,1)*C24} -> 0 | G24: =G23 -> 2 | H24: 1
A25: Output | B25: Total Number of Spacing Conveyors | C25: =+C18*C12 -> 0 | D25: {=INDEX('Induct line for Arm'!D7:D8,'Arm Sorter'!G25,'Arm Sorter'!H25)} -> 130948.54 | E25: =C25*D25 -> 0 | F25: {=INDEX('Induct line for Arm'!F7:F8,G25,1)*C25} -> 0 | G25: =G24 -> 2 | H25: 1
A26: Output | B26: Total Number of Receiving Conveyors | C26: =C12*C19 -> 0 | D26: =+((C20/1000)*'Quote Master'!$I$4)+'Quote Master'!$I$5 -> 180740.74 | E26: =C26*D26*0.6 -> 0 | F26: 0 | G26: =G25 -> 2 | H26: 1
A27: Output | B27: Total Number of Launchpad Conveyors | C27: =+C12*C14 -> 0 | D27: =+((C15/1000)*'Quote Master'!$I$4)+'Quote Master'!$I$5 -> 180740.74 | E27: =C27*D27*0.6 -> 0 | F27: 0 | G27: =G26 -> 2 | H27: 1
D28: Total | E28: =SUM(E23:E27) -> 0 | F28: =SUM(F23:F27) -> 0
A29: Output | B29: Total Cost of Induct Conveyors | C29: =E28 -> 0
A30: Output | B30: Total Cost of Cable Tray and Legs | C30: =F28*'Induct line for Arm'!D11 -> 0
A31: Output | B31: Total Cost Control Panel | C31: =+C12*'Induct line for Arm'!D10 -> 0
A32: Output | B32: Total Inducts Cost | C32: =SUM(C29:C31) -> 0
B33: Total Inductions | C33: =+(C12) -> 0
B34: Required Hand Barcode scanner for Semi-Auto mode | C34: Yes
B35: Hand Barcode Scanner for semi-auto mode | C35: =+IF(C34="Yes",(C33*'Quote Master'!$I$72),0) -> 0
B36: Recommended Sale Price | C36: =(C32/H1)+C35 -> 0
B37: Enter Number of Weighing Conveyors(Total) | C37: 0
B38: Select Weighing Model | C38: Bizerba WM CWL
B39: Weighing Conveyor Price | C39: =+VLOOKUP(C38,'Weighing Conveyors'!$D$1:$L$8,9,FALSE)*C37 -> 0
B42: Total Sale Price for Arm Sorter | C42: =+C36+F9+C39 -> 16890000

Sheet Swedi sorter
A1: S.No. | B1: Description | C1: Quantity | D1: UOM | E1: Unit Price | F1: Total | G1: Sales Factor | H1: ='Overall Costing'!$M$1 -> 0.675
A2: 1 | B2: Swedi | C2: 0 | D2: Nos | E2: 0 | F2: =(E2/$H$1)*C2 -> 0 | G2: Swedi Costing and Calculation sheet
A3: 2 | B3: ICR 890 8K | C3: 0 | D3: Nos | E3: =VLOOKUP(B3,'Quote Master'!$C$107:$I$112,7,0) -> 2800671.5 | F3: =E3*C3 -> 0
A4: 3 | B4: VMS 4200 | C4: 0 | D4: Nos | E4: =VLOOKUP(B4,'Quote Master'!$C$107:$I$112,7,0) -> 1375000 | F4: =E4*C4 -> 0
A5: 4 | B5: PLC Based contoller | D5: Nos | E5: =+'Quote Master'!I102 -> 800000 | F5: =+E5*C5 -> 0
A6: 5 | B6: Server PC | D6: Nos | E6: =+'Quote Master'!I106 -> 250000 | F6: =E6*C6 -> 0
A7: 6 | B7: HAA Server | D7: Nos | E7: =+'Quote Master'!I103 -> 2121000 | F7: =E7*C7 -> 0
B8: Field and Wiring | F8: =F2*'Overall Costing'!$M$3 -> 0
A9: 7 | E9: Total | F9: =SUM(F2:F8) -> 0
A11: 8 | B11: Enter the Total Number of Inducts in the System | C11: 0
A12: 9 | B12: Width of Induct Conveyors | C12: 800 mm
A13: 10 | B13: Enter number of Launchpad conveyors | C13: 1
A14: 11 | B14: Enter Length of Launchpad conveyor(mm) | C14: 1000
A15: 12 | B15: Enter number of Angle Merge Conveyors per Induct | C15: 1
A16: 13 | B16: Enter Number of Short Buffer Conveyors per Induct | C16: 1
A17: 14 | B17: Enter Number of Spacing Conveyors per Induct | C17: 1
A18: 15 | B18: Enter Number of Receiving Conveyor | C18: 1
A19: 16 | B19: Enter length of Receiving Conveyor(mm) | C19: 2000
A20: 17 | B20: Enter Total Number of intermediate Conveyors | C20: 0
A21: 18 | B21: Enter length of intermediate Conveyor(mm) | C21: 2000
A24: Output | D24: Unit Price | E24: Total Price | F24: Length (for Cable Tray and Leg Calculation) | G24: Row | H24: Column
A25: Output | B25: Total Number of Angle Merge Conveyors | C25: =+C11*C15 -> 0 | D25: {=INDEX('Induct Line for Swedi'!D3:E5,'Swedi sorter'!G25,'Swedi sorter'!H25)} -> 148710.38 | E25: =C25*D25 -> 0 | F25: {=INDEX('Induct Line for Swedi'!F3:F5,G25,1)*C25} -> 0 | G25: =MATCH($C$12,'Induct Line for Swedi'!C3:C5,0) -> 2 | H25: 1
A26: Output | B26: Total Number of Short Buffer Conveyors | C26: =+C16*C11 -> 0 | D26: {=INDEX('Induct Line for Swedi'!D6:D8,'Swedi sorter'!G26,'Swedi sorter'!H26)} -> 125379.79 | E26: =C26*D26 -> 0 | F26: {=INDEX('Induct Line for Swedi'!F6:F8,G26,1)*C26} -> 0 | G26: =G25 -> 2 | H26: 1
A27: Output | B27: Total Number of Spacing Conveyors | C27: =+C17*C11 -> 0 | D27: {=INDEX('Induct Line for Swedi'!D9:D11,G27,H27)} -> 130948.54 | E27: =C27*D27 -> 0 | F27: {=INDEX('Induct Line for Swedi'!F9:F11,G27,1)*C27} -> 0 | G27: =G26 -> 2 | H27: 1
A28: Output | B28: Total Number of Receiving Conveyors | C28: =C11*C18 -> 0 | D28: =+((C19/1000)*'Quote Master'!$I$4)+'Quote Master'!$I$5 -> 217777.78 | E28: =(C28*D28)*0.6 -> 0 | F28: 0 | G28: =G27 -> 2 | H28: 1
A29: Output | B29: Total Number of Launchpad Conveyors | C29: =+C11*C13 -> 0 | D29: =+((C14/1000)*'Quote Master'!$I$4)+'Quote Master'!$I$5 -> 199259.26 | E29: =C29*D29*0.6 -> 0 | F29: 0 | G29: =G28 -> 2 | H29: 1
A30: Output | B30: Total Number of Intermediate Conveyors | C30: =+C20 -> 0 | D30: =+((C21/1000)*'Quote Master'!$I$4)+'Quote Master'!$I$5 -> 217777.78 | E30: =C30*D30*0.6 -> 0 | F30: 0 | G30: =G29 -> 2 | H30: 1
D31: Total | E31: =SUM(E25:E29) -> 0 | F31: =SUM(F25:F29) -> 0
A32: Output | B32: Total Cost of Induct Conveyors | C32: =E31 -> 0
A33: Output | B33: Total Cost of Cable Tray and Legs | C33: =F31*'Induct Line for Swedi'!D14 -> 0
A34: Output | B34: Total Cost Control Panel | C34: =+C11*'Induct Line for Swedi'!D13 -> 0
A35: Output | B35: Total Inducts Cost | C35: =SUM(C32:C34) -> 0
B36: Total Inductions | C36: =+(C11) -> 0
B37: Required Hand Barcode scanner for Semi-Auto mode | C37: Yes
B38: Hand Barcode Scanner for semi-auto mode | C38: =+IF(C37="Yes",(C36*'Quote Master'!$I$72),0) -> 0
B39: Recommended Sale Price | C39: =(C35/H1)+C38 -> 0
B40: Enter Number of Weighing Conveyors(Total) | C40: 0
B41: Select Weighing Model | C41: Bizerba WM CWL
B42: Weighing Conveyor Price | C42: =+VLOOKUP(C41,'Weighing Conveyors'!$D$1:$L$8,9,FALSE)*C40 -> 0
B44: Total Sale Price for Swedi Sorter with Inducts | C44: =+C39+F9+C42 -> 0

Sheet Conveyors
P1: Sales Factor | Q1: ='Overall Costing'!M1 -> 0.675
A2: S No. | B2: Name | C2: ANGLE | D2: EL_1 | E2: EL_2 | F2: Conveyor Length (mm) | G2: Conveyor Length (m) | H2: Conveyor width (mm) | I2: Set | J2: Unit Price | K2: Drive Price | L2: MOTOR_POWER (KW) | M2: Base Module (BM) HM+TM+DM | N2: Motor Price(Inculding {Pannel, VFD}) | O2: Cost/ mtr | P2: Total Cost Price | Q2: Selling Price | R2: Family | S2: Price in Euro
A3: 1 | B3: PVC Belt Conveyor(Bulk loading) | C3: 0 | D3: 4050 | E3: 4050 | F3: 5760 | G3: =F3/1000 -> 5.76 | H3: 1210 | I3: 1 | L3: =IF(C3<=0,4,5.5) -> 4 | M3: =VLOOKUP(H3,'Conveyor Costing'!$B$3:$F$7,5,0)*3 -> 381531.85 | N3: =VLOOKUP(L3,'Conveyor Costing'!$T$24:$AB$38,9,0) -> 143651.5 | O3: =VLOOKUP(H3,'Conveyor Costing'!$B$3:$G$7,6,0)*3 -> 55400.098 | P3: =IF(G3<2.4,((M3+((0)*O3))+N3)*I3,((M3+((G3-2.4)*O3))+N3)*I3) -> 711327.68 | Q3: =P3/$Q$1 -> 1053818.8 | R3: Infeed | S3: =Q3/'Overall Costing'!$M$5 -> 11210.838
A4: 2 | B4: PVC Belt Conveyor(Bulk loading) | C4: 0 | D4: 550 | E4: 550 | F4: 5760 | G4: =F4/1000 -> 5.76 | H4: 1210 | I4: 1 | L4: =IF(C4<=0,4,5.5) -> 4 | M4: =VLOOKUP(H4,'Conveyor Costing'!$B$3:$F$7,5,0)*3 -> 381531.85 | N4: =VLOOKUP(L4,'Conveyor Costing'!$T$24:$AB$38,9,0) -> 143651.5 | O4: =VLOOKUP(H4,'Conveyor Costing'!$B$3:$G$7,6,0)*3 -> 55400.098 | P4: =IF(G4<2.4,((M4+((0)*O4))+N4)*I4,((M4+((G4-2.4)*O4))+N4)*I4) -> 711327.68 | Q4: =P4/$Q$1 -> 1053818.8 | R4: Infeed | S4: =Q4/'Overall Costing'!$M$5 -> 11210.838
A5: 3 | B5: PVC Belt Conveyor | C5: 14.3 | D5: 3548 | E5: 5180 | F5: 6440 | G5: =F5/1000 -> 6.44 | H5: 1210 | I5: 1 | L5: =IF(C5<=0,4,5.5) -> 5.5 | M5: =VLOOKUP(H5,'Conveyor Costing'!$B$3:$F$7,5,0)*2 -> 254354.57 | N5: =VLOOKUP(L5,'Conveyor Costing'!$T$24:$AB$38,9,0) -> 169290 | O5: =VLOOKUP(H5,'Conveyor Costing'!$B$3:$G$7,6,0)*2 -> 36933.399 | P5: =IF(G5<2.4,((M5+((0)*O5))+N5)*I5,((M5+((G5-2.4)*O5))+N5)*I5) -> 572855.5 | Q5: =P5/$Q$1 -> 848674.81 | R5: Infeed | S5: =Q5/'Overall Costing'!$M$5 -> 9028.4554
A6: 4 | B6: PVC Belt Conveyor | C6: 0 | D6: 550 | E6: 550 | F6: 5760 | G6: =F6/1000 -> 5.76 | H6: 1210 | I6: 1 | L6: =IF(C6<=0,4,5.5) -> 4 | M6: =VLOOKUP(H6,'Conveyor Costing'!$B$3:$F$7,5,0)*2 -> 254354.57 | N6: =VLOOKUP(L6,'Conveyor Costing'!$T$24:$AB$38,9,0) -> 143651.5 | O6: =VLOOKUP(H6,'Conveyor Costing'!$B$3:$G$7,6,0)*2 -> 36933.399 | P6: =IF(G6<2.4,((M6+((0)*O6))+N6)*I6,((M6+((G6-2.4)*O6))+N6)*I6) -> 522102.29 | Q6: =P6/$Q$1 -> 773484.87 | R6: Infeed | S6: =Q6/'Overall Costing'!$M$5 -> 8228.5624
A7: 5 | B7: PVC Belt Conveyor | C7: 14.8 | D7: 2350 | E7: 4433 | F7: 8000 | G7: =F7/1000 -> 8 | H7: 1210 | I7: 1 | L7: 7.5 | M7: =VLOOKUP(H7,'Conveyor Costing'!$B$3:$F$7,5,0)*2 -> 254354.57 | N7: =VLOOKUP(L7,'Conveyor Costing'!$T$24:$AB$38,9,0) -> 249400 | O7: =VLOOKUP(H7,'Conveyor Costing'!$B$3:$G$7,6,0)*2 -> 36933.399 | P7: =IF(G7<2.4,((M7+((0)*O7))+N7)*I7,((M7+((G7-2.4)*O7))+N7)*I7) -> 710581.6 | Q7: =P7/$Q$1 -> 1052713.5 | R7: Infeed | S7: =Q7/'Overall Costing'!$M$5 -> 11199.08
